<sdf version='1.4'>
  <model name='quadrotor'>
    <link name='base_link'>
      <pose>0 0 0 0 -0 0</pose>
      <inertial>
        <pose>0 0 0 0 -0 0</pose>
        <mass>1.477</mass>
        <inertia>
          <ixx>0.01152</ixx>
          <ixy>0</ixy>
          <ixz>0</ixz>
          <iyy>0.01152</iyy>
          <iyz>0</iyz>
          <izz>0.0218</izz>
        </inertia>
      </inertial>
      <collision name='base_link_collision'>
        <pose>0 0 0 0 -0 0</pose>
        <geometry>
          <mesh>
            <scale>1 1 1</scale>
            <uri>model://quadrotor/meshes/quadrotor/quadrotor_base.stl</uri>
          </mesh>
        </geometry>
      </collision>
      <visual name='base_link_visual'>
        <pose>0 0 0 0 -0 0</pose>
        <geometry>
          <mesh>
            <scale>1 1 1</scale>
            <uri>model://quadrotor/meshes/quadrotor/quadrotor_base.dae</uri>
          </mesh>
        </geometry>
      </visual>
      <velocity_decay>
        <linear>0</linear>
        <angular>0</angular>
      </velocity_decay>
    </link>
    <link name='laser_tilt'>
      <pose>0.15 0 -0.097 0 -0 0</pose>
      <inertial>
        <pose>-0.001134 0.001667 -0.007067 0 -0 0</pose>
        <mass>0.00592</mass>
        <inertia>
          <ixx>0.001296</ixx>
          <ixy>2.3e-05</ixy>
          <ixz>3.7e-05</ixz>
          <iyy>0.001086</iyy>
          <iyz>3.5e-05</iyz>
          <izz>0.000895</izz>
        </inertia>
      </inertial>
      <collision name='laser_tilt_collision'>
        <pose>0 0 0 0 -0 0</pose>
        <geometry>
          <mesh>
            <scale>1 1 1</scale>
            <uri>model://pr2/meshes/tilting_laser_v0/tilting_hokuyo_L.stl</uri>
          </mesh>
        </geometry>
        <surface>
          <contact>
            <ode/>
          </contact>
          <friction>
            <ode/>
          </friction>
        </surface>
      </collision>
      <visual name='laser_tilt_visual'>
        <pose>0 0 0 0 -0 0</pose>
        <geometry>
          <mesh>
            <scale>1 1 1</scale>
            <uri>model://pr2/meshes/tilting_laser_v0/tilting_hokuyo.dae</uri>
          </mesh>
        </geometry>
      </visual>
      <gravity>1</gravity>
      <velocity_decay>
        <linear>0</linear>
        <angular>0</angular>
      </velocity_decay>
      <self_collide>0</self_collide>
      <sensor name='laser0' type='ray'>
        <always_on>1</always_on>
        <update_rate>40</update_rate>
        <pose>0 0 0 0 -0 0</pose>
        <visualize>1</visualize>
        <ray>
          <scan>
            <horizontal>
              <samples>1081</samples>
              <resolution>1</resolution>
              <min_angle>-2.35619</min_angle>
              <max_angle>2.35619</max_angle>
            </horizontal>
          </scan>
          <range>
            <min>0.08</min>
            <max>30</max>
            <resolution>0.01</resolution>
          </range>
        </ray>
        <plugin name='gazebo_ros_laser0_controller' filename='libgazebo_ros_laser.so'>
          <gaussianNoise>0.005</gaussianNoise>
          <alwaysOn>true</alwaysOn>
          <updateRate>40</updateRate>
          <topicName>scan</topicName>
          <frameName>laser_tilt</frameName>
        </plugin>
      </sensor>
    </link>
    <joint name='laser_joint' type='revolute'>
      <child>laser_tilt</child>
      <parent>base_link</parent>
      <axis>
        <xyz>0 1 0</xyz>
        <limit>
          <lower>-0.7854</lower>
          <upper>1.48353</upper>
          <effort>0</effort>
          <velocity>4</velocity>
        </limit>
        <dynamics>
          <damping>0.008</damping>
        </dynamics>
      </axis>
    </joint>
    <plugin name='joint_state_publisher' filename='libjoint_state_publisher.so'>
      <jointName>laser_joint</jointName>
      <updateRate>100.0</updateRate>
      <alwaysOn>true</alwaysOn>
    </plugin>
    <plugin name='quadrotor_controller' filename='libgazebo_ros_control.so'>
      <controlPeriod>0.01</controlPeriod>
      <robotSimType>hector_quadrotor_controller_gazebo/QuadrotorHardwareSim</robotSimType>
    </plugin>
    <static>0</static>
    <plugin name='quadrotor_groundtruth_sim' filename='libgazebo_ros_p3d.so'>
      <updateRate>100.0</updateRate>
      <bodyName>base_link</bodyName>
      <topicName>ground_truth/state</topicName>
      <gaussianNoise>0.0</gaussianNoise>
      <frameName>world</frameName>
    </plugin>
  </model>
</sdf>
