<?xml version="1.0" ?>
<!-- =================================================================================== -->
<!-- |    This document was autogenerated by xacro from quadrotor_hokuyo_utm30lx.urdf.xacro | -->
<!-- |    EDITING THIS FILE BY HAND IS NOT RECOMMENDED                                 | -->
<!-- =================================================================================== -->
<robot name="quadrotor" xmlns:xacro="http://ros.org/wiki/xacro">
  <!-- Included URDF Files -->
  <!-- Instantiate quadrotor_base_macro once (has no parameters atm) -->
  <link name="base_link">
    <inertial>
      <mass value="1.477"/>
      <origin xyz="0 0 0"/>
      <inertia ixx="0.01152" ixy="0.0" ixz="0.0" iyy="0.01152" iyz="0.0" izz="0.0218"/>
    </inertial>
    <visual>
      <origin rpy="0 0 0" xyz="0 0 0"/>
      <geometry>
        <mesh filename="file:///home/sherpa/LaserScan_workspaces/laser_ws/src/quadrotor/meshes/quadrotor/quadrotor_base.dae"/>
      </geometry>
    </visual>
    <collision>
      <origin rpy="0 0 0" xyz="0 0 0"/>
      <geometry>
        <mesh filename="file:///home/sherpa/LaserScan_workspaces/laser_ws/src/quadrotor/meshes/quadrotor/quadrotor_base.stl"/>
      </geometry>
    </collision>
  </link>

  <link name="laser_tilt">
      <visual name='laser_tilt_mount_link_geom_visual'>
        <geometry>
          <!--<mesh filename="/home/franzo/ROS_workspaces/gazebo_ws/src/gazebo_tutorials/meshes/box_n_laser/tilting_hokuyo.dae"/>-->
	  <mesh filename="model://pr2/meshes/tilting_laser_v0/tilting_hokuyo.dae"/>
        </geometry>
      </visual>
    <collision name="laser_collision">
      <geometry>
        <!--<mesh filename="/home/franzo/ROS_workspaces/gazebo_ws/src/gazebo_tutorials/meshes/box_n_laser/tilting_hokuyo_L.stl"/>-->
	<mesh filename="model://pr2/meshes/tilting_laser_v0/tilting_hokuyo_L.stl"/>
      </geometry>  	
    </collision>
    <inertial>
      <mass value="0.592000" />
      <origin xyz="-0.001134 0.001667 -0.007067" rpy="0 0 0"/>
      <inertia ixx="0.001296" ixy="0.000023" ixz="0.000037"
        iyy="0.001086" iyz="0.000035"
        izz="0.000895" />
    </inertial>
    
  </link>

<gazebo reference="laser_tilt">
  <sensor name="laser" type="ray">
    <update_rate>40.000000</update_rate>
    <pose>0.000000 0.000000 0.030000 0.000000 -0.000000 0.000000</pose>
    <ray>
      	<scan>
            <horizontal>
              <samples>640</samples>
              <resolution>1.000000</resolution>
              <min_angle>-1.396263</min_angle>
              <max_angle>1.396263</max_angle>
            </horizontal>
        </scan>
     	  
        <range>
          <min>0.08</min>
          <max>10.0</max>
          <resolution>0.01</resolution>
        </range>
    </ray>

		<always_on>true</always_on>
    <plugin name="laser" filename="libRayPlugin.so"/>
    <always_on>1</always_on>
    <update_rate>30</update_rate>
    <visualize>true</visualize>
   
  </sensor>
</gazebo>
  

  <joint name="laser_joint" type="revolute">
    <!--<origin xyz=".15 0 .055" rpy="0 0 0" />-->
    <origin xyz=".15 0 -0.097" rpy="0 0 0" />
    <parent link="base_link" />
    <child link="laser_tilt" />
    <axis xyz="0 1 0"/>
    <limit effort="0.0" lower="-0.785400" upper="1.483530" velocity="4.0"/>
    <dynamics damping="0.008" friction="0.0"/>
  </joint>

  <!-- Forward facing camera -->
  <!--<xacro:include filename="$(find hector_sensors_description)/urdf/generic_camera.urdf.xacro" />
    <xacro:generic_camera name="front_cam" parent="base_link" ros_topic="camera/image" cam_info_topic="camera/camera_info" update_rate="10" res_x="320" res_y="240" image_format="R8G8B8" hfov="90">
      <origin xyz="0.05 0.0 -0.06" rpy="0 0 0"/>
    </xacro:generic_camera>-->
</robot>
